2025-10-30 16:50:56 | ERROR    | __main__                       | download_yahoo_finance | Failed to download BTC-USD: 'timestamp'
Traceback (most recent call last):
  File "C:\Users\saill\Desktop\nautilus\.venv\Lib\site-packages\pandas\core\indexes\base.py", line 3812, in get_loc
    return self._engine.get_loc(casted_key)
           ~~~~~~~~~~~~~~~~~~~~^^^^^^^^^^^^
  File "pandas/_libs/index.pyx", line 167, in pandas._libs.index.IndexEngine.get_loc
  File "pandas/_libs/index.pyx", line 196, in pandas._libs.index.IndexEngine.get_loc
  File "pandas/_libs/hashtable_class_helper.pxi", line 7088, in pandas._libs.hashtable.PyObjectHashTable.get_item
  File "pandas/_libs/hashtable_class_helper.pxi", line 7096, in pandas._libs.hashtable.PyObjectHashTable.get_item
KeyError: 'timestamp'

The above exception was the direct cause of the following exception:

Traceback (most recent call last):
  File "C:\Users\saill\Desktop\nautilus\scripts\data_download.py", line 112, in download_yahoo_finance
    f"Date range: {df['timestamp'].min()} to {df['timestamp'].max()}"
                   ~~^^^^^^^^^^^^^
  File "C:\Users\saill\Desktop\nautilus\.venv\Lib\site-packages\pandas\core\frame.py", line 4113, in __getitem__
    indexer = self.columns.get_loc(key)
  File "C:\Users\saill\Desktop\nautilus\.venv\Lib\site-packages\pandas\core\indexes\base.py", line 3819, in get_loc
    raise KeyError(key) from err
KeyError: 'timestamp'
2025-10-30 16:50:56 | ERROR    | __main__                       | main                 | Failed to download data
2025-10-30 16:51:12 | ERROR    | __main__                       | download_yahoo_finance | Failed to download BTC-USD: 'timestamp'
Traceback (most recent call last):
  File "C:\Users\saill\Desktop\nautilus\.venv\Lib\site-packages\pandas\core\indexes\base.py", line 3812, in get_loc
    return self._engine.get_loc(casted_key)
           ~~~~~~~~~~~~~~~~~~~~^^^^^^^^^^^^
  File "pandas/_libs/index.pyx", line 167, in pandas._libs.index.IndexEngine.get_loc
  File "pandas/_libs/index.pyx", line 196, in pandas._libs.index.IndexEngine.get_loc
  File "pandas/_libs/hashtable_class_helper.pxi", line 7088, in pandas._libs.hashtable.PyObjectHashTable.get_item
  File "pandas/_libs/hashtable_class_helper.pxi", line 7096, in pandas._libs.hashtable.PyObjectHashTable.get_item
KeyError: 'timestamp'

The above exception was the direct cause of the following exception:

Traceback (most recent call last):
  File "C:\Users\saill\Desktop\nautilus\scripts\data_download.py", line 112, in download_yahoo_finance
    f"Date range: {df['timestamp'].min()} to {df['timestamp'].max()}"
                   ~~^^^^^^^^^^^^^
  File "C:\Users\saill\Desktop\nautilus\.venv\Lib\site-packages\pandas\core\frame.py", line 4113, in __getitem__
    indexer = self.columns.get_loc(key)
  File "C:\Users\saill\Desktop\nautilus\.venv\Lib\site-packages\pandas\core\indexes\base.py", line 3819, in get_loc
    raise KeyError(key) from err
KeyError: 'timestamp'
2025-10-30 16:51:12 | ERROR    | __main__                       | main                 | Failed to download data
2025-10-30 16:51:45 | ERROR    | __main__                       | download_yahoo_finance | Failed to download ETH-USD: 'timestamp'
Traceback (most recent call last):
  File "C:\Users\saill\Desktop\nautilus\.venv\Lib\site-packages\pandas\core\indexes\base.py", line 3812, in get_loc
    return self._engine.get_loc(casted_key)
           ~~~~~~~~~~~~~~~~~~~~^^^^^^^^^^^^
  File "pandas/_libs/index.pyx", line 167, in pandas._libs.index.IndexEngine.get_loc
  File "pandas/_libs/index.pyx", line 196, in pandas._libs.index.IndexEngine.get_loc
  File "pandas/_libs/hashtable_class_helper.pxi", line 7088, in pandas._libs.hashtable.PyObjectHashTable.get_item
  File "pandas/_libs/hashtable_class_helper.pxi", line 7096, in pandas._libs.hashtable.PyObjectHashTable.get_item
KeyError: 'timestamp'

The above exception was the direct cause of the following exception:

Traceback (most recent call last):
  File "C:\Users\saill\Desktop\nautilus\scripts\data_download.py", line 112, in download_yahoo_finance
    f"Date range: {df['timestamp'].min()} to {df['timestamp'].max()}"
                   ~~^^^^^^^^^^^^^
  File "C:\Users\saill\Desktop\nautilus\.venv\Lib\site-packages\pandas\core\frame.py", line 4113, in __getitem__
    indexer = self.columns.get_loc(key)
  File "C:\Users\saill\Desktop\nautilus\.venv\Lib\site-packages\pandas\core\indexes\base.py", line 3819, in get_loc
    raise KeyError(key) from err
KeyError: 'timestamp'
2025-10-30 16:51:45 | ERROR    | __main__                       | main                 | Failed to download data
2025-10-30 17:00:55 | ERROR    | execution.backtest_runner      | initialize_engine    | Failed to initialize backtest engine: Unexpected keyword argument 'logging_config'
Traceback (most recent call last):
  File "C:\Users\saill\Desktop\nautilus\execution\backtest_runner.py", line 114, in initialize_engine
    engine_config = BacktestEngineConfig(
        trader_id=f"BACKTESTER-{self.config.name.replace(' ', '_').upper()}",
        logging_config={"bypass": False},  # Use our logging
    )
TypeError: Unexpected keyword argument 'logging_config'
2025-10-30 17:00:55 | ERROR    | __main__                       | main                 | Backtest failed: Unexpected keyword argument 'logging_config'
Traceback (most recent call last):
  File "C:\Users\saill\Desktop\nautilus\scripts\run_backtest.py", line 278, in main
    runner.initialize_engine()
    ~~~~~~~~~~~~~~~~~~~~~~~~^^
  File "C:\Users\saill\Desktop\nautilus\execution\backtest_runner.py", line 114, in initialize_engine
    engine_config = BacktestEngineConfig(
        trader_id=f"BACKTESTER-{self.config.name.replace(' ', '_').upper()}",
        logging_config={"bypass": False},  # Use our logging
    )
TypeError: Unexpected keyword argument 'logging_config'
